<?xml version="1.0" ?>
<!-- =================================================================================== -->
<!-- |    This document was autogenerated by xacro from summit_xl_omni.urdf.xacro      | -->
<!-- |    EDITING THIS FILE BY HAND IS NOT RECOMMENDED                                 | -->
<!-- =================================================================================== -->
<robot name="summit_xl">
  <!-- ***************** -->
  <!-- Imported elements -->
  <!-- ***************** -->
  <!-- First we import all posible elements defined in the urdf.xacro files. All these elements are defined as macro:xacros -->
  <gazebo reference="base_footprint">
    <material>Gazebo/Green</material>
  </gazebo>
  <!-- in kg-->
  <!-- in kg-->
  <!-- source en.wikipedia.org/wiki/List_of_moments_of_inertia-->
  <!-- This file unifies all sensors that can be used on simulation, defined as xacro:macros -->
  <!-- <xacro:macro name="sensor_ultrasonic_a21_gazebo">
    <gazebo reference="${prefix}_link">
			<xacro:if value="${gpu}">
        <xacro:property name="ray_type" value="gpu_ray" />
        <xacro:property name="plugin_lib" value="libgazebo_ros_gpu_laser.so" />
      </xacro:if>
      <xacro:unless value="${gpu}">
        <xacro:property name="ray_type" value="ray" />
        <xacro:property name="plugin_lib" value="libgazebo_ros_laser.so" />
      </xacro:unless>
			<sensor type="${ray_type}" name="${prefix}_sensor">
				<pose>0 0 0 0 0 0</pose>
				<visualize>false</visualize>
				<update_rate>40</update_rate>
				<ray>
					<scan>
						<horizontal>
							<samples>1081</samples>
							<resolution>1</resolution>
							<min_angle>${min_angle}</min_angle>
							<max_angle>${max_angle}</max_angle>
						</horizontal>
					</scan>
					<range>
						<min>0.06</min>
						<max>20.0</max>
						<! resolution>0.004363323</resolution >
						<resolution>0.004359297</resolution>
						<! resolution>0.001</resolution >
					</range>
					<noise>
						<type>gaussian</type>
						<mean>0.0</mean>
						<stddev>0.01</stddev>
					</noise>
				</ray>
				<plugin name="${prefix}_controller" filename="${plugin_lib}">
					<topicName>${prefix_topic}/scan</topicName>
					<frameName>/${prefix}_link</frameName>
				</plugin>
			</sensor>
	</gazebo>
  </xacro:macro>
  -->
  <!-- Includes -->
  <!-- Includes -->
  <gazebo>
    <plugin filename="libgazebo_ros_control.so" name="ros_control">
      <robotParam>robot_description</robotParam>
      <controlPeriod>0.001</controlPeriod>
      <robotSimType>gazebo_ros_control/DefaultRobotHWSim</robotSimType>
      <legacyModeNS>true</legacyModeNS>
    </plugin>
  </gazebo>
  <!-- *************** -->
  <!-- Robots Elements -->
  <!-- *************** -->
  <!-- Here we create the robot elements using the xacro:macros imported at the beggining of this file -->
  <link name="summit_xl_base_footprint">
    <visual>
      <origin rpy="0 0 0" xyz="0 0 0"/>
      <geometry>
        <box size="0.001 0.001 0.001"/>
      </geometry>
    </visual>
  </link>
  <joint name="summit_xl_base_footprint_joint" type="fixed">
    <origin rpy="0 0 0" xyz="0 0 0.11"/>
    <!-- ${wheel_radius} property must be defined inside wheel description -->
    <parent link="summit_xl_base_footprint"/>
    <child link="summit_xl_base_link"/>
  </joint>
  <!-- BASE_LINK -->
  <link name="summit_xl_base_link">
    <inertial>
      <mass value="25.0"/>
      <origin xyz="0 0 0"/>
      <inertia ixx="1.391" ixy="0.004" ixz="0.0" iyy="6.853" iyz="0.0" izz="6.125"/>
    </inertial>
    <visual>
      <origin rpy="0 0 0" xyz="0 0 0"/>
      <geometry>
        <mesh filename="package://summit_xl_description/meshes/bases/summit_xl_chassis.dae"/>
      </geometry>
      <material name="darkgrey">
        <color rgba="0.1 0.1 0.1 1"/>
      </material>
    </visual>
    <collision>
      <origin rpy="0 0 0 " xyz="0 0 0"/>
      <geometry>
        <mesh filename="package://summit_xl_description/meshes/bases/summit_xl_chassis_collision.dae"/>
      </geometry>
    </collision>
  </link>
  <!-- DOCKING CONTACTS -->
  <joint name="summit_xl_base_docking_joint" type="fixed">
    <origin rpy="0 0 0 " xyz="0.284 0.012 0.068"/>
    <parent link="summit_xl_base_link"/>
    <child link="summit_xl_base_docking_contact_link"/>
  </joint>
  <!-- DOCKING LINK -->
  <link name="summit_xl_base_docking_contact_link"/>
  <joint name="summit_xl_front_right_wheel_joint" type="continuous">
    <parent link="summit_xl_base_link"/>
    <child link="summit_xl_front_right_wheel_link"/>
    <origin rpy="0 0 0" xyz="0.229 -0.235 0.0"/>
    <axis rpy="0 0 0" xyz="0 1 0"/>
    <limit effort="100" velocity="100"/>
    <joint_properties damping="0.0" friction="0.0"/>
  </joint>
  <link name="summit_xl_front_right_wheel_link">
    <visual>
      <origin rpy="0 0 0" xyz="0 0 0"/>
      <geometry>
        <mesh filename="package://summit_xl_description/meshes/wheels/omni_wheel_2.dae"/>
      </geometry>
      <material name="darkgrey">
        <color rgba="0.2 0.2 0.2 1"/>
      </material>
    </visual>
    <collision>
      <origin rpy="0 0 0" xyz="0 0 0"/>
      <geometry>
        <mesh filename="package://summit_xl_description/meshes/wheels/omni_wheel_2.dae"/>
        <!--sphere radius="${omni_wheel_radius}" /-->
        <!-- <cylinder length="${omni_wheel_height}" radius="${omni_wheel_radius}" /> -->
        <!-- sphere radius="${omni_wheel_radius}"/-->
      </geometry>
    </collision>
    <inertial>
      <mass value="6.5"/>
      <origin xyz="0 0 0"/>
      <inertia ixx="0.0303095" ixy="0" ixz="0" iyy="0.05241925" iyz="0" izz="0.0303095"/>
    </inertial>
  </link>
  <!-- Transmission is important to link the joints and the controller (see summit_xl_control/config/summit_xl_control.yaml)-->
  <transmission name="summit_xl_front_right_wheel_joint_trans">
    <type>transmission_interface/SimpleTransmission</type>
    <joint name="summit_xl_front_right_wheel_joint">
      <hardwareInterface>hardware_interface/VelocityJointInterface</hardwareInterface>
    </joint>
    <actuator name="summit_xl_front_right_wheel_joint_motor">
      <mechanicalReduction>1</mechanicalReduction>
    </actuator>
  </transmission>
  <gazebo reference="summit_xl_front_right_wheel_link">
    <mu1 value="0.0"/>
    <mu2 value="0.0"/>
    <kp value="10000000.0"/>
    <kd value="1.0"/>
    <fdir1 value="1 0 0"/>
    <turnGravityOff>false</turnGravityOff>
  </gazebo>
  <joint name="summit_xl_front_left_wheel_joint" type="continuous">
    <parent link="summit_xl_base_link"/>
    <child link="summit_xl_front_left_wheel_link"/>
    <origin rpy="0 0 0" xyz="0.229 0.235 0.0"/>
    <axis rpy="0 0 0" xyz="0 1 0"/>
    <limit effort="100" velocity="100"/>
    <joint_properties damping="0.0" friction="0.0"/>
  </joint>
  <link name="summit_xl_front_left_wheel_link">
    <visual>
      <origin rpy="0 0 0" xyz="0 0 0"/>
      <geometry>
        <mesh filename="package://summit_xl_description/meshes/wheels/omni_wheel_1.dae"/>
      </geometry>
      <material name="darkgrey">
        <color rgba="0.2 0.2 0.2 1"/>
      </material>
    </visual>
    <collision>
      <origin rpy="0 0 0" xyz="0 0 0"/>
      <geometry>
        <mesh filename="package://summit_xl_description/meshes/wheels/omni_wheel_1.dae"/>
        <!--sphere radius="${omni_wheel_radius}" /-->
        <!-- <cylinder length="${omni_wheel_height}" radius="${omni_wheel_radius}" /> -->
        <!-- sphere radius="${omni_wheel_radius}"/-->
      </geometry>
    </collision>
    <inertial>
      <mass value="6.5"/>
      <origin xyz="0 0 0"/>
      <inertia ixx="0.0303095" ixy="0" ixz="0" iyy="0.05241925" iyz="0" izz="0.0303095"/>
    </inertial>
  </link>
  <!-- Transmission is important to link the joints and the controller (see summit_xl_control/config/summit_xl_control.yaml)-->
  <transmission name="summit_xl_front_left_wheel_joint_trans">
    <type>transmission_interface/SimpleTransmission</type>
    <joint name="summit_xl_front_left_wheel_joint">
      <hardwareInterface>hardware_interface/VelocityJointInterface</hardwareInterface>
    </joint>
    <actuator name="summit_xl_front_left_wheel_joint_motor">
      <mechanicalReduction>1</mechanicalReduction>
    </actuator>
  </transmission>
  <gazebo reference="summit_xl_front_left_wheel_link">
    <mu1 value="0.0"/>
    <mu2 value="0.0"/>
    <kp value="10000000.0"/>
    <kd value="1.0"/>
    <fdir1 value="1 0 0"/>
    <turnGravityOff>false</turnGravityOff>
  </gazebo>
  <joint name="summit_xl_back_left_wheel_joint" type="continuous">
    <parent link="summit_xl_base_link"/>
    <child link="summit_xl_back_left_wheel_link"/>
    <origin rpy="0 0 0" xyz="-0.229 0.235 0.0"/>
    <axis rpy="0 0 0" xyz="0 1 0"/>
    <limit effort="100" velocity="100"/>
    <joint_properties damping="0.0" friction="0.0"/>
  </joint>
  <link name="summit_xl_back_left_wheel_link">
    <visual>
      <origin rpy="0 0 0" xyz="0 0 0"/>
      <geometry>
        <mesh filename="package://summit_xl_description/meshes/wheels/omni_wheel_1.dae"/>
      </geometry>
      <material name="darkgrey">
        <color rgba="0.2 0.2 0.2 1"/>
      </material>
    </visual>
    <collision>
      <origin rpy="0 0 0" xyz="0 0 0"/>
      <geometry>
        <mesh filename="package://summit_xl_description/meshes/wheels/omni_wheel_1.dae"/>
        <!--sphere radius="${omni_wheel_radius}" /-->
        <!-- <cylinder length="${omni_wheel_height}" radius="${omni_wheel_radius}" /> -->
        <!-- sphere radius="${omni_wheel_radius}"/-->
      </geometry>
    </collision>
    <inertial>
      <mass value="6.5"/>
      <origin xyz="0 0 0"/>
      <inertia ixx="0.0303095" ixy="0" ixz="0" iyy="0.05241925" iyz="0" izz="0.0303095"/>
    </inertial>
  </link>
  <!-- Transmission is important to link the joints and the controller (see summit_xl_control/config/summit_xl_control.yaml)-->
  <transmission name="summit_xl_back_left_wheel_joint_trans">
    <type>transmission_interface/SimpleTransmission</type>
    <joint name="summit_xl_back_left_wheel_joint">
      <hardwareInterface>hardware_interface/VelocityJointInterface</hardwareInterface>
    </joint>
    <actuator name="summit_xl_back_left_wheel_joint_motor">
      <mechanicalReduction>1</mechanicalReduction>
    </actuator>
  </transmission>
  <gazebo reference="summit_xl_back_left_wheel_link">
    <mu1 value="0.0"/>
    <mu2 value="0.0"/>
    <kp value="10000000.0"/>
    <kd value="1.0"/>
    <fdir1 value="1 0 0"/>
    <turnGravityOff>false</turnGravityOff>
  </gazebo>
  <joint name="summit_xl_back_right_wheel_joint" type="continuous">
    <parent link="summit_xl_base_link"/>
    <child link="summit_xl_back_right_wheel_link"/>
    <origin rpy="0 0 0" xyz="-0.229 -0.235 0.0"/>
    <axis rpy="0 0 0" xyz="0 1 0"/>
    <limit effort="100" velocity="100"/>
    <joint_properties damping="0.0" friction="0.0"/>
  </joint>
  <link name="summit_xl_back_right_wheel_link">
    <visual>
      <origin rpy="0 0 0" xyz="0 0 0"/>
      <geometry>
        <mesh filename="package://summit_xl_description/meshes/wheels/omni_wheel_2.dae"/>
      </geometry>
      <material name="darkgrey">
        <color rgba="0.2 0.2 0.2 1"/>
      </material>
    </visual>
    <collision>
      <origin rpy="0 0 0" xyz="0 0 0"/>
      <geometry>
        <mesh filename="package://summit_xl_description/meshes/wheels/omni_wheel_2.dae"/>
        <!--sphere radius="${omni_wheel_radius}" /-->
        <!-- <cylinder length="${omni_wheel_height}" radius="${omni_wheel_radius}" /> -->
        <!-- sphere radius="${omni_wheel_radius}"/-->
      </geometry>
    </collision>
    <inertial>
      <mass value="6.5"/>
      <origin xyz="0 0 0"/>
      <inertia ixx="0.0303095" ixy="0" ixz="0" iyy="0.05241925" iyz="0" izz="0.0303095"/>
    </inertial>
  </link>
  <!-- Transmission is important to link the joints and the controller (see summit_xl_control/config/summit_xl_control.yaml)-->
  <transmission name="summit_xl_back_right_wheel_joint_trans">
    <type>transmission_interface/SimpleTransmission</type>
    <joint name="summit_xl_back_right_wheel_joint">
      <hardwareInterface>hardware_interface/VelocityJointInterface</hardwareInterface>
    </joint>
    <actuator name="summit_xl_back_right_wheel_joint_motor">
      <mechanicalReduction>1</mechanicalReduction>
    </actuator>
  </transmission>
  <gazebo reference="summit_xl_back_right_wheel_link">
    <mu1 value="0.0"/>
    <mu2 value="0.0"/>
    <kp value="10000000.0"/>
    <kd value="1.0"/>
    <fdir1 value="1 0 0"/>
    <turnGravityOff>false</turnGravityOff>
  </gazebo>
  <joint name="summit_xl_imu_joint" type="fixed">
    <axis xyz="1 0 0"/>
    <!--origin xyz="0 0 0.2825"/-->
    <origin rpy="0 0 0" xyz="-0.18 0.0 0.170"/>
    <parent link="summit_xl_base_link"/>
    <child link="summit_xl_imu_link"/>
  </joint>
  <link name="summit_xl_imu_link">
    <inertial>
      <origin rpy="0 0 0" xyz="0.0 0 0.01"/>
      <mass value="0.005"/>
      <inertia ixx="8.333333333333334e-10" ixy="0" ixz="0" iyy="8.333333333333334e-10" iyz="0" izz="8.333333333333334e-10"/>
    </inertial>
    <visual>
      <origin rpy="0 0 0" xyz="0 0 0"/>
      <geometry>
        <box size="0.001 0.001 0.001"/>
      </geometry>
    </visual>
    <!--collision>
	        <origin rpy="0 0 0" xyz="0 0 0"/>
	        <geometry>
	          <box size="0.001 0.001 0.001"/>
	        </geometry>
	      </collision-->
  </link>
  <!--<gazebo>-->
  <!--<plugin name="${prefix}_controller" filename="libgazebo_ros_imu.so">-->
  <!--<topicName>${ns}imu/data</topicName>-->
  <!--<serviceName>imu/service</serviceName>-->
  <!--<bodyName>${prefix}_link</bodyName>-->
  <!--<updateRateHZ>50.0</updateRateHZ>-->
  <!--<gaussianNoise>0.0</gaussianNoise>-->
  <!--</plugin>-->
  <!--</gazebo>-->
  <gazebo reference="summit_xl_imu_link">
    <gravity>true</gravity>
    <sensor name="summit_xl_imu_imu_sensor" type="imu">
      <always_on>true</always_on>
      <update_rate>100</update_rate>
      <visualize>true</visualize>
      <topic>__default_topic__</topic>
      <plugin filename="libgazebo_ros_imu_sensor.so" name="summit_xl_imu_imu_plugin">
        <topicName>imu/data_raw</topicName>
        <bodyName>summit_xl_imu_link</bodyName>
        <updateRateHZ>100.0</updateRateHZ>
        <gaussianNoise>0.0</gaussianNoise>
        <xyzOffset>0 0 0</xyzOffset>
        <rpyOffset>0 0 0</rpyOffset>
        <frameName>summit_xl_imu_link</frameName>
      </plugin>
      <pose>0 0 0 0 0 0</pose>
    </sensor>
  </gazebo>
  <joint name="summit_xl_front_laser_base_joint" type="fixed">
    <origin rpy="0 0 0" xyz="0.0 0.0 0.2726"/>
    <parent link="summit_xl_base_link"/>
    <child link="summit_xl_front_laser_base_link"/>
  </joint>
  <link name="summit_xl_front_laser_base_link">
    <collision>
      <origin rpy="0 0 0" xyz="0 0 0.0"/>
      <geometry>
        <box size="0.010 0.010 0.010"/>
      </geometry>
    </collision>
    <visual>
      <origin rpy="0 0 0" xyz="0 0 0.0"/>
      <geometry>
        <mesh filename="package://robotnik_sensors/meshes/hokuyo_ust_20lx.dae"/>
      </geometry>
    </visual>
    <inertial>
      <origin rpy="0 0 0" xyz="0.0 0 0.035"/>
      <mass value="0.130"/>
      <inertia ixx="8.016666666666669e-05" ixy="0" ixz="0" iyy="8.016666666666669e-05" iyz="0" izz="5.4166666666666685e-05"/>
    </inertial>
  </link>
  <link name="summit_xl_front_laser_link">
	</link>
  <joint name="summit_xl_front_laser_joint" type="fixed">
    <parent link="summit_xl_front_laser_base_link"/>
    <child link="summit_xl_front_laser_link"/>
    <origin rpy="0 0 0" xyz="0.00 0.0 0.0474"/>
  </joint>
  <gazebo reference="summit_xl_front_laser_link">
    <sensor name="summit_xl_front_laser_sensor" type="ray">
      <pose>0 0 0 0 0 0</pose>
      <visualize>false</visualize>
      <update_rate>40</update_rate>
      <ray>
        <scan>
          <horizontal>
            <samples>1081</samples>
            <resolution>1</resolution>
            <min_angle>-2.3562</min_angle>
            <max_angle>2.3562</max_angle>
          </horizontal>
        </scan>
        <range>
          <min>0.06</min>
          <max>20.0</max>
          <!-- resolution>0.004363323</resolution -->
          <resolution>0.004359297</resolution>
          <!-- resolution>0.001</resolution -->
        </range>
        <noise>
          <type>gaussian</type>
          <mean>0.0</mean>
          <stddev>0.01</stddev>
        </noise>
      </ray>
      <plugin filename="libgazebo_ros_laser.so" name="summit_xl_front_laser_controller">
        <topicName>front_laser/scan</topicName>
        <frameName>/summit_xl_front_laser_link</frameName>
      </plugin>
    </sensor>
  </gazebo>
  <joint name="summit_xl_front_ptz_camera_joint" type="fixed">
    <axis xyz="0 0 1"/>
    <origin rpy="0 0.2617993877991494 0" xyz="0.185 0 0.1967"/>
    <parent link="summit_xl_base_link"/>
    <child link="summit_xl_front_ptz_camera_base_link"/>
  </joint>
  <link name="summit_xl_front_ptz_camera_base_link">
    <inertial>
      <origin rpy="0 1.5707963267948966 0" xyz="0.0  0.0 -0.015"/>
      <mass value="0.8"/>
      <inertia ixx="0.0023232000000000005" ixy="0" ixz="0" iyy="0.002701866666666667" iyz="0" izz="0.002701866666666667"/>
    </inertial>
    <visual>
      <origin rpy="0 0 0" xyz="0.0 0.0 0.0"/>
      <!-- because the origin of the mesh file is not at the "center" of the model-->
      <material name="axis_color">
        <color rgba="0.1 0.1 0.1 1"/>
      </material>
      <geometry>
        <mesh filename="package://robotnik_sensors/meshes/axis_p5514.stl" scale="1.0 1.0 1.0"/>
      </geometry>
    </visual>
    <collision>
      <origin rpy="0 0 0" xyz="0.0 0.0 0.0"/>
      <!-- because the origin of the mesh file is not at the "center" of the model-->
      <geometry>
        <mesh filename="package://robotnik_sensors/meshes/axis_p5514.stl" scale="1.0 1.0 1.0"/>
      </geometry>
    </collision>
  </link>
  <joint name="summit_xl_front_ptz_camera_pan_joint" type="revolute">
    <axis xyz="0 0 1"/>
    <origin rpy="0 0 0" xyz="0.0 0.0 0.0"/>
    <!-- check the displacement -->
    <parent link="summit_xl_front_ptz_camera_base_link"/>
    <child link="summit_xl_front_ptz_camera_pan_link"/>
    <limit effort="1.0" lower="-3.1415" upper="3.1415" velocity="1.0"/>
    <joint_properties damping="0.1" friction="{ptz_joint_friction}"/>
  </joint>
  <link name="summit_xl_front_ptz_camera_pan_link">
    <inertial>
      <mass value="0.1"/>
      <origin rpy="0 0 0" xyz="0 0 0"/>
      <inertia ixx="0.0002016666666666667" ixy="0" ixz="0" iyy="0.00018416666666666668" iyz="0" izz="0.00018416666666666668"/>
    </inertial>
  </link>
  <transmission name="summit_xl_front_ptz_camera_pan_trans">
    <type>transmission_interface/SimpleTransmission</type>
    <joint name="summit_xl_front_ptz_camera_pan_joint">
      <hardwareInterface>hardware_interface/VelocityJointInterface</hardwareInterface>
    </joint>
    <actuator name="pan_motor">
      <hardwareInterface>hardware_interface/VelocityJointInterface</hardwareInterface>
      <mechanicalReduction>1.0</mechanicalReduction>
    </actuator>
  </transmission>
  <joint name="summit_xl_front_ptz_camera_tilt_joint" type="revolute">
    <axis xyz="0 0 1"/>
    <origin rpy="-1.5707963267948966 0 0" xyz="0.0 0.0 0.0"/>
    <parent link="summit_xl_front_ptz_camera_pan_link"/>
    <child link="summit_xl_front_ptz_camera_tilt_link"/>
    <limit effort="1.0" lower="-1.5708" upper="1.5708" velocity="1.0"/>
    <joint_properties damping="0.1" friction="{ptz_joint_friction}"/>
  </joint>
  <link name="summit_xl_front_ptz_camera_tilt_link">
    <inertial>
      <mass value="0.1"/>
      <origin rpy="0 0 0" xyz="0 0 0"/>
      <inertia ixx="0.00018416666666666668" ixy="0" ixz="0" iyy="0.00018416666666666668" iyz="0" izz="0.0002016666666666667"/>
    </inertial>
  </link>
  <transmission name="summit_xl_front_ptz_camera_tilt_trans">
    <type>transmission_interface/SimpleTransmission</type>
    <joint name="summit_xl_front_ptz_camera_tilt_joint">
      <hardwareInterface>hardware_interface/VelocityJointInterface</hardwareInterface>
    </joint>
    <actuator name="tilt_motor">
      <hardwareInterface>hardware_interface/VelocityJointInterface</hardwareInterface>
      <mechanicalReduction>1.0</mechanicalReduction>
    </actuator>
  </transmission>
  <joint name="summit_xl_front_ptz_camera_frame_joint" type="fixed">
    <origin rpy="0 0 0" xyz="0.0 0 0"/>
    <parent link="summit_xl_front_ptz_camera_tilt_link"/>
    <child link="summit_xl_front_ptz_camera_frame_link"/>
  </joint>
  <link name="summit_xl_front_ptz_camera_frame_link">
    <inertial>
      <mass value="0.1"/>
      <origin xyz="0 0 0"/>
      <inertia ixx="0.00018416666666666668" ixy="0" ixz="0" iyy="0.00018416666666666668" iyz="0" izz="0.0002016666666666667"/>
    </inertial>
  </link>
  <!-- Optical frame -->
  <joint name="summit_xl_front_ptz_camera_optical_joint" type="fixed">
    <origin rpy="-1.5707963267948966 0 -1.5707963267948966" xyz="0 0 0"/>
    <parent link="summit_xl_front_ptz_camera_frame_link"/>
    <child link="summit_xl_front_ptz_camera_optical_frame_link"/>
  </joint>
  <link name="summit_xl_front_ptz_camera_optical_frame_link">
    <inertial>
      <mass value="0.1"/>
      <origin xyz="0 0 0"/>
      <inertia ixx="0.00018416666666666668" ixy="0" ixz="0" iyy="0.00018416666666666668" iyz="0" izz="0.0002016666666666667"/>
    </inertial>
  </link>
  <gazebo reference="summit_xl_front_ptz_camera_base_link">
    <material>Gazebo/FlatBlack</material>
  </gazebo>
  <gazebo reference="summit_xl_front_ptz_camera_frame_link">
    <sensor name="summit_xl_front_ptz_camera_sensor" type="camera">
      <update_rate>30.0</update_rate>
      <camera>
        <horizontal_fov>1.0471975511965976</horizontal_fov>
        <image>
          <format>R8G8B8</format>
          <width>640</width>
          <height>480</height>
        </image>
        <clip>
          <near>0.05</near>
          <far>8.0</far>
        </clip>
      </camera>
      <plugin filename="libgazebo_ros_camera.so" name="summit_xl_front_ptz_camera_controller">
        <alwaysOn>true</alwaysOn>
        <updateRate>0.0</updateRate>
        <cameraName>summit_xl_front_ptz_camera</cameraName>
        <imageTopicName>image_raw</imageTopicName>
        <cameraInfoTopicName>camera_info</cameraInfoTopicName>
        <frameName>/summit_xl_front_ptz_camera_optical_frame_link</frameName>
        <hackBaseline>0.0</hackBaseline>
        <distortionK1>0.0</distortionK1>
        <distortionK2>0.0</distortionK2>
        <distortionK3>0.0</distortionK3>
        <distortionT1>0.0</distortionT1>
        <distortionT2>0.0</distortionT2>
      </plugin>
    </sensor>
  </gazebo>
  <joint name="summit_xl_front_rgbd_camera_joint" type="fixed">
    <origin rpy="0 0 0" xyz="0.324 0.012 0.172"/>
    <parent link="summit_xl_base_link"/>
    <child link="summit_xl_front_rgbd_camera_link"/>
  </joint>
  <link name="summit_xl_front_rgbd_camera_link">
    <visual>
      <origin rpy="0 0 0" xyz="0 0 0"/>
      <geometry>
        <mesh filename="package://robotnik_sensors/meshes/orbbec_astra.dae"/>
      </geometry>
    </visual>
    <collision>
      <geometry>
        <mesh filename="package://robotnik_sensors/meshes/orbbec_astra.dae"/>
      </geometry>
    </collision>
    <inertial>
      <mass value="0.001"/>
      <origin xyz="0.0 0.0 0.0"/>
      <inertia ixx="2.3437500000000006e-06" ixy="0" ixz="0" iyy="2.0833333333333336e-07" iyz="0" izz="2.4020833333333336e-06"/>
    </inertial>
  </link>
  <joint name="summit_xl_front_rgbd_camera_rgb_joint" type="fixed">
    <origin rpy="0.0 0.0 0.0" xyz="0.0 0.0125 0.0150"/>
    <parent link="summit_xl_front_rgbd_camera_link"/>
    <child link="summit_xl_front_rgbd_camera_rgb_frame"/>
  </joint>
  <link name="summit_xl_front_rgbd_camera_rgb_frame">
    <inertial>
      <mass value="0.297"/>
      <origin xyz="-0.02 -0.0125 0.0"/>
      <inertia ixx="0.0006960937500000001" ixy="0" ixz="0" iyy="6.1875e-05" iyz="0" izz="0.00071341875"/>
    </inertial>
  </link>
  <joint name="summit_xl_front_rgbd_camera_rgb_optical_joint" type="fixed">
    <origin rpy="-1.5707963267948966 0 -1.5707963267948966" xyz="0.0 0.0 0.0"/>
    <parent link="summit_xl_front_rgbd_camera_rgb_frame"/>
    <child link="summit_xl_front_rgbd_camera_rgb_optical_frame"/>
  </joint>
  <link name="summit_xl_front_rgbd_camera_rgb_optical_frame">
    <inertial>
      <mass value="0.001"/>
      <origin rpy="1.5707963267948966 0 1.5707963267948966" xyz="0 0 0"/>
      <inertia ixx="2.3437500000000006e-06" ixy="0" ixz="0" iyy="2.0833333333333336e-07" iyz="0" izz="2.4020833333333336e-06"/>
    </inertial>
  </link>
  <joint name="summit_xl_front_rgbd_camera_depth_joint" type="fixed">
    <origin rpy="0 0 0" xyz="0.0 0.0375 0.0150"/>
    <parent link="summit_xl_front_rgbd_camera_link"/>
    <child link="summit_xl_front_rgbd_camera_depth_frame"/>
  </joint>
  <link name="summit_xl_front_rgbd_camera_depth_frame">
    <inertial>
      <mass value="0.001"/>
      <origin xyz="0 0 0"/>
      <inertia ixx="2.3437500000000006e-06" ixy="0" ixz="0" iyy="2.0833333333333336e-07" iyz="0" izz="2.4020833333333336e-06"/>
    </inertial>
  </link>
  <joint name="summit_xl_front_rgbd_camera_depth_optical_joint" type="fixed">
    <origin rpy="-1.5707963267948966 0 -1.5707963267948966" xyz="0 0 0"/>
    <parent link="summit_xl_front_rgbd_camera_depth_frame"/>
    <child link="summit_xl_front_rgbd_camera_depth_optical_frame"/>
  </joint>
  <link name="summit_xl_front_rgbd_camera_depth_optical_frame">
    <inertial>
      <mass value="0.001"/>
      <origin xyz="0 0 0"/>
      <inertia ixx="2.3437500000000006e-06" ixy="0" ixz="0" iyy="2.0833333333333336e-07" iyz="0" izz="2.4020833333333336e-06"/>
    </inertial>
  </link>
  <gazebo reference="summit_xl_front_rgbd_camera_link">
    <sensor name="summit_xl_front_rgbd_camera_depth_sensor" type="depth">
      <always_on>true</always_on>
      <update_rate>20.0</update_rate>
      <camera>
        <horizontal_fov>1.0471975511965976</horizontal_fov>
        <image>
          <format>R8G8B8</format>
          <width>640</width>
          <height>480</height>
        </image>
        <clip>
          <near>0.05</near>
          <far>3.5</far>
        </clip>
      </camera>
      <plugin filename="libgazebo_ros_openni_kinect.so" name="summit_xl_front_rgbd_camera_controller">
        <cameraName>front_rgbd_camera</cameraName>
        <alwaysOn>true</alwaysOn>
        <updateRate>10</updateRate>
        <imageTopicName>rgb/image_raw</imageTopicName>
        <depthImageTopicName>depth/image_raw</depthImageTopicName>
        <pointCloudTopicName>depth/points</pointCloudTopicName>
        <cameraInfoTopicName>rgb/camera_info</cameraInfoTopicName>
        <depthImageCameraInfoTopicName>depth/camera_info</depthImageCameraInfoTopicName>
        <frameName>/summit_xl_front_rgbd_camera_depth_optical_frame</frameName>
        <baseline>0.1</baseline>
        <distortion_k1>0.0</distortion_k1>
        <distortion_k2>0.0</distortion_k2>
        <distortion_k3>0.0</distortion_k3>
        <distortion_t1>0.0</distortion_t1>
        <distortion_t2>0.0</distortion_t2>
        <pointCloudCutoff>0.4</pointCloudCutoff>
      </plugin>
    </sensor>
  </gazebo>
  <!-- MAST OF THE ANTENNA GPS -->
  <joint name="summit_xl_gps_joint" type="fixed">
    <axis xyz="0 1 0"/>
    <origin rpy="0 0 0" xyz="-0.22 0 0.275"/>
    <parent link="summit_xl_base_link"/>
    <child link="summit_xl_gps_mast_base_link"/>
  </joint>
  <link name="summit_xl_gps_mast_base_link">
    <inertial>
      <origin rpy="0 0 0" xyz="0.0 0 0.0"/>
      <mass value="1.0"/>
      <inertia ixx="0.020841666666666665" ixy="0" ixz="0" iyy="0.020841666666666665" iyz="0" izz="1.6666666666666667e-05"/>
    </inertial>
    <visual>
      <origin rpy="0 0 0" xyz="0 0 0"/>
      <material name="mast_color">
        <color rgba="0.1 0.1 0.1 1"/>
      </material>
      <geometry>
        <cylinder length="0.5" radius="0.01"/>
      </geometry>
    </visual>
    <collision>
      <origin rpy="0 0 0" xyz="0 0 0"/>
      <geometry>
        <cylinder length="0.5" radius="0.01"/>
      </geometry>
    </collision>
  </link>
  <joint name="summit_xl_gps_mast_joint" type="fixed">
    <axis xyz="0 1 0"/>
    <parent link="summit_xl_gps_mast_base_link"/>
    <child link="summit_xl_gps_base_link"/>
    <origin rpy="0 0 0" xyz="0 0 0.25"/>
  </joint>
  <gazebo reference="summit_xl_gps_mast_base_link">
    <material>Gazebo/Black</material>
    <gravity>true</gravity>
  </gazebo>
  <!-- ANTENNA GPS -->
  <link name="summit_xl_gps_base_link">
    <inertial>
      <origin rpy="0 0 0" xyz="0.0 0 0.015"/>
      <mass value="0.2"/>
      <inertia ixx="0.00012435" ixy="0" ixz="0" iyy="0.00012435" iyz="0" izz="0.00021870000000000003"/>
    </inertial>
    <visual>
      <origin rpy="0 0 0" xyz="0 0 0"/>
      <material name="gps_color">
        <color rgba="1 1 1 1"/>
      </material>
      <geometry>
        <mesh filename="package://robotnik_sensors/meshes/antenna_3GO16.stl" scale="1.0 1.0 1.0"/>
      </geometry>
    </visual>
    <collision>
      <origin rpy="0 0 0" xyz="0 0 0"/>
      <geometry>
        <mesh filename="package://robotnik_sensors/meshes/antenna_3GO16.stl" scale="1.0 1.0 1.0"/>
      </geometry>
    </collision>
  </link>
  <gazebo reference="summit_xl_gps_base_link">
    <material>Gazebo/White</material>
    <gravity>true</gravity>
  </gazebo>
  <gazebo>
    <plugin filename="libhector_gazebo_ros_gps.so" name="summit_xl_gps_controller">
      <alwaysOn>1</alwaysOn>
      <updateRate>5</updateRate>
      <bodyName>summit_xl_gps_base_link</bodyName>
      <!-- must be the link of the gps device, not the base_link or base_footprint -->
      <frameId>summit_xl_gps_base_link</frameId>
      <!-- which frame_id would be on the published message -->
      <topicName>gps/fix</topicName>
      <!-- GPS coordinates -->
      <referenceLatitude>0</referenceLatitude>
      <referenceLongitude>0</referenceLongitude>
      <!-- To set heading in ENU orientation (degrees) -->
      <referenceHeading>90</referenceHeading>
      <velocityTopicName>gps/fix_velocity</velocityTopicName>
      <drift>0.0 0.0 0.0</drift>
      <!--<drift>0.0001 0.0001 0.0001</drift>-->
      <!--<drift>0.3 0.3 0.3</drift>-->
      <gaussianNoise>0.00001 0.00001 0.00001</gaussianNoise>
      <!--<gaussianNoise>0.00001 0.00001 0.00001</gaussianNoise>-->
      <velocityDrift>0.00001 0.00001 0.00001</velocityDrift>
      <!--<velocityGaussianNoise>0.1 0.1 0.1</velocityGaussianNoise>-->
      <velocityGaussianNoise>0.00001 0.00001 0.00001</velocityGaussianNoise>
    </plugin>
  </gazebo>
</robot>
